scripts/test_case9.txt
40
0 o
1 o
2 o
3 o
4 o
5 o
6 o
7 o
8 o
9 o
10 o
11 o
12 o
13 o
14 o
15 o
16 o
17 o
18 o
19 o
20 o
21 o
22 o
23 o
24 o
25 o
26 o
27 o
28 o
29 o
30 o
31 o
32 o
33 o
34 o
35 o
36 o
37 o
38 o
39 o
.
39 S 45645167 MSFT 95020 1127
38 S 40032805 MSFT 6886 6163
39 B 8003321 GOOG 90626 3368
38 B 78652107 AMZN 96668 1248
38 B 66449078 AAPL 26657 101
38 B 33865104 GOOG 75434 6917
39 C 45645167
37 S 12113189 AAPL 75035 6799
39 B 42695415 MSFT 52656 1017
38 S 74378146 AAPL 51285 1006
39 C 45645167
37 S 38994101 AMZN 40943 9015
39 S 67020053 MSFT 87360 3910
35 B 86114179 GOOG 9319 8384
39 S 63930880 MSFT 90247 5019
39 S 70110992 AAPL 72487 5565
37 S 75613915 GOOG 89198 1034
39 B 82726161 MSFT 72058 6844
37 S 73233756 AMZN 6805 9418
36 B 14373430 AAPL 85276 5130
38 S 83226748 AMZN 51238 7788
39 S 67036965 GOOG 54613 4954
37 C 73233756
39 S 81658713 MSFT 77254 1607
37 B 16699153 AAPL 42991 1455
39 S 20120189 GOOG 99505 3535
39 S 37763916 AMZN 46986 8206
39 B 51494579 GOOG 28340 9253
39 S 67927842 MSFT 1601 1276
39 C 45645167
34 S 58647724 AMZN 44836 995
35 B 19994635 AMZN 70963 4075
38 B 51136280 MSFT 59171 3355
38 C 83226748
39 S 72995373 MSFT 72908 1553
35 C 19994635
37 C 73233756
38 B 11897313 AAPL 10235 6147
39 S 19971755 AMZN 89352 2397
39 S 11670996 GOOG 43085 3786
39 B 62819703 AMZN 70200 7308
39 B 84460527 AMZN 22793 7803
38 B 8277548 GOOG 98786 2238
39 C 72995373
37 S 4940793 MSFT 94078 4457
39 B 25743156 GOOG 86661 2343
39 B 22648309 MSFT 83374 2124
39 B 35373805 MSFT 67109 7570
37 S 61300859 AMZN 84239 1803
39 C 25743156
39 C 51494579
39 B 48772722 AMZN 7477 9558
39 S 47726235 AMZN 5595 405
39 C 35373805
38 B 65272239 AAPL 86202 2730
38 B 57688536 AMZN 91238 7794
39 C 62819703
38 C 51136280
38 S 53858385 AAPL 80540 8620
38 C 11897313
39 B 92179336 MSFT 29035 8375
39 C 8003321
37 S 37321157 AMZN 88763 6530
39 C 72995373
38 S 87286560 AAPL 87710 1380
33 S 46442058 GOOG 20708 6960
38 B 58634705 MSFT 23476 9291
33 B 78995232 AMZN 47214 8838
37 B 92640021 AMZN 90470 9260
39 C 19971755
38 C 57688536
38 C 33865104
38 C 66449078
37 C 16699153
37 B 79860353 AAPL 50218 8810
39 S 58762596 GOOG 15192 847
38 S 42850151 MSFT 27361 8042
39 S 11211327 AMZN 33058 1630
38 C 11897313
38 S 59095941 AAPL 50944 8423
38 B 2075875 AMZN 59729 4968
39 S 3616566 AAPL 23934 8334
39 C 8003321
35 S 65946516 GOOG 27044 6165
39 S 72948641 GOOG 70241 6349
39 C 70110992
36 S 90738457 AAPL 2402 8959
36 S 88389427 MSFT 66573 8872
39 B 53482470 AMZN 36788 343
39 B 27363339 MSFT 65961 4798
39 B 13309099 AMZN 95905 9264
38 C 42850151
39 B 43048149 AMZN 66313 9134
39 S 20002513 AAPL 43194 2454
39 C 62819703
34 C 58647724
38 C 66449078
37 C 4940793
39 C 82726161
37 C 16699153
37 C 37321157
39 B 90578045 AMZN 38349 6012
39 C 11670996
39 S 36148423 AAPL 91497 1228
37 S 47348088 MSFT 44622 1345
39 B 29361671 MSFT 56487 770
39 S 7122391 GOOG 93249 7346
38 C 8277548
39 S 72580650 GOOG 28629 666
39 B 33299284 AAPL 36409 6658
37 B 73631229 AMZN 41772 8568
39 B 92112523 MSFT 28230 4638
38 B 54922841 GOOG 24898 3200
38 S 95463494 AAPL 66312 8099
37 S 84455872 MSFT 44383 1169
39 C 11211327
38 C 54922841
39 S 30485637 AMZN 48936 5527
38 S 66807932 AMZN 83268 1157
39 C 13309099
39 S 45591463 MSFT 26720 8249
36 S 30164511 GOOG 48514 9616
38 B 51534902 GOOG 29237 4789
39 B 74403243 AAPL 84221 9054
38 C 83226748
39 C 42695415
39 S 9135727 AAPL 64813 568
36 S 78564983 GOOG 92068 6328
38 S 74762094 GOOG 11037 1213
38 S 86813050 MSFT 28804 8715
39 S 76352837 MSFT 77018 4795
39 S 23465727 AMZN 58704 6010
33 C 46442058
37 S 31528184 AMZN 80254 4704
39 C 51494579
39 S 11933684 AAPL 40267 4178
39 S 44467246 AMZN 6118 360
39 B 87931976 MSFT 21026 9672
39 C 92112523
38 B 50815758 AAPL 71036 8703
35 S 94017542 AMZN 13409 4867
39 B 17716514 AMZN 54303 1493
39 S 42878278 AAPL 69233 2890
39 C 29361671
39 S 85190284 AAPL 7239 146
39 S 66483958 MSFT 10058 6831
39 B 32667326 AMZN 10667 9022
39 C 44467246
39 S 76115735 MSFT 45209 2170
39 S 98241509 AMZN 92063 3232
39 B 21435336 GOOG 82434 9649
38 S 69459619 AMZN 19430 7847
39 S 68964940 AAPL 50589 3758
38 S 34040103 MSFT 26949 104
39 C 47726235
38 S 99894323 MSFT 47227 6599
38 B 90288400 AMZN 39788 7132
32 S 38074481 AMZN 86827 7376
37 S 44359692 MSFT 42125 8326
37 C 44359692
38 S 4820988 AAPL 95589 3691
39 S 56530647 AMZN 53516 178
39 C 67020053
39 C 35373805
37 C 31528184
36 C 88389427
39 C 84460527
39 B 22039549 MSFT 49721 4917
39 B 42826201 AAPL 21847 229
38 C 8277548
39 C 11670996
39 C 17716514
37 S 25545942 GOOG 85989 8394
37 S 92671290 AMZN 84783 8719
37 S 66988238 AAPL 12349 2352
39 B 83665027 AAPL 80597 9578
39 S 70004535 MSFT 27168 178
39 S 94951526 MSFT 71709 2034
38 S 55365025 AMZN 74381 3158
37 B 28472671 AMZN 74714 9809
38 C 54922841
36 C 30164511
37 B 54045961 MSFT 83689 4048
38 B 80380467 GOOG 3138 5655
39 S 44625475 GOOG 11506 7848
39 S 75553391 MSFT 83466 8485
37 B 25386030 GOOG 55276 8239
37 S 67363417 MSFT 55495 3496
38 B 71831986 AMZN 50370 9392
38 C 65272239
36 S 72235048 AAPL 43240 8961
36 C 90738457
35 S 2802696 MSFT 10248 8822
37 B 56954099 GOOG 89146 504
38 S 92441237 AMZN 4388 5541
38 S 37471544 AAPL 51340 5976
37 B 69936156 AAPL 59707 5434
38 S 87168313 MSFT 25785 2124
34 S 97006413 AMZN 46637 5844
38 S 84463576 AMZN 68331 3293
37 S 42894711 AMZN 22347 8438
38 S 921480 GOOG 21608 9102
38 C 99894323
37 C 84455872
38 S 97184897 MSFT 59422 522
38 C 921480
38 C 58634705
37 S 99700264 GOOG 6684 3847
38 C 55365025
36 B 85304 GOOG 61649 6353
38 C 33865104
38 C 11897313
38 C 90288400
36 B 34307687 AMZN 35861 4818
38 C 53858385
37 S 13206516 MSFT 47637 3542
38 S 58748169 GOOG 7629 3457
38 S 38100421 MSFT 75874 7847
37 S 68390925 MSFT 10032 7505
35 C 65946516
37 S 11367841 AMZN 56650 1611
38 B 23458941 GOOG 20105 2883
38 C 74378146
37 B 11386802 MSFT 2132 3220
38 B 37832463 AMZN 16543 1797
38 S 65055055 GOOG 78585 8295
38 S 60757740 MSFT 99586 7323
38 C 50815758
38 S 42753731 GOOG 53382 6075
36 S 12695976 AMZN 99550 3151
37 B 9840487 AAPL 51488 825
37 C 13206516
36 S 34398541 AMZN 52255 5682
38 C 50815758
35 C 94017542
38 B 32512594 GOOG 83767 9700
38 S 89749721 AMZN 24798 6173
37 C 25545942
33 C 78995232
36 B 61100076 AAPL 4109 449
38 S 31293071 GOOG 38828 6257
36 C 72235048
36 B 28697577 MSFT 84896 983
36 C 14373430
38 S 57604194 GOOG 50290 6592
38 C 51534902
36 S 23703482 AAPL 11262 9435
38 C 8277548
37 S 10780322 AAPL 73839 1470
38 C 80380467
38 S 85771475 MSFT 28217 6707
38 B 27026620 MSFT 48743 9960
38 C 31293071
38 C 92441237
35 C 2802696
37 S 58788888 MSFT 23127 8740
38 B 61837146 GOOG 25605 3765
38 S 13889930 AMZN 78326 2215
38 B 22466259 AMZN 19014 362
38 S 79812003 GOOG 35124 3406
38 C 87168313
36 S 44585796 AMZN 18044 2883
38 B 98535098 AMZN 27318 1054
38 C 37471544
37 C 73233756
38 C 90288400
36 B 18250678 AAPL 79732 2434
38 C 65272239
37 B 12040265 AAPL 15909 4177
38 C 66449078
38 S 46085022 AAPL 20834 5059
37 S 9486100 GOOG 2129 5389
38 B 95944931 AAPL 91182 1233
38 S 17652361 MSFT 10604 6414
36 S 43439110 AMZN 99019 6182
38 B 3098845 AAPL 64279 9571
37 C 47348088
34 B 57510334 MSFT 67218 5568
34 S 22301956 MSFT 65906 1086
37 C 73631229
37 B 33880302 GOOG 2794 8110
36 C 44585796
34 C 97006413
38 B 98275745 MSFT 94130 7752
35 C 86114179
38 B 99570807 AAPL 30073 6942
35 B 14684208 MSFT 63212 7044
37 C 79860353
37 C 75613915
38 C 42850151
34 S 98219516 GOOG 96519 80
37 C 16699153
38 B 53373450 GOOG 18565 4592
37 B 40681397 AAPL 38955 119
36 B 89442279 GOOG 93170 6693
36 B 26137053 AAPL 44912 3915
37 C 61300859
37 S 1791011 AAPL 77134 2130
37 C 33880302
37 B 62885587 MSFT 69774 6944
37 B 44767963 GOOG 43806 7619
37 C 11386802
37 B 13144073 MSFT 56365 3742
36 S 30997537 MSFT 68102 3994
36 B 91030210 MSFT 76700 6268
37 B 65624250 AAPL 82987 5838
37 C 73631229
37 B 78128387 MSFT 18105 733
36 B 86560871 AMZN 46556 2714
37 C 73631229
35 B 42231717 AAPL 20350 8488
36 C 86560871
37 C 61300859
36 C 72235048
37 B 63829389 GOOG 5222 9415
36 C 12695976
37 S 83816556 AMZN 34419 6101
37 S 89403493 AAPL 4486 785
36 S 94176215 AMZN 27305 915
36 C 18250678
36 C 86560871
